<?xml version="1.0"?>
<robot xmlns:xacro="http://www.ros.org/wiki/xacro" name="AutoCrane">

    <!-- params definition -->

    <!-- macro definition -->
    <xacro:macro name="default_origin">
        <origin xyz="0 0 0" rpy="0 0 0" />
    </xacro:macro>

    <xacro:macro name="box_geometry" params="length width height">
        <geometry>
            <box size="${length} ${width} ${height}" />
        </geometry>
    </xacro:macro>


    <!-- * * * Link Definitions * * * -->

    <link name="base_link">
        <visual>
            <xacro:default_origin />
            <xacro:box_geometry length="0.1" width="0.1" height="2" />
            <material name="m1">
                <color rgba="0 0.9 0.9 1.0"/>
            </material>
        </visual>
        <collision>
            <xacro:box_geometry length="0.1" width="0.1" height="2" />
            <xacro:default_origin />
        </collision>
    </link>

    <link name="arm">
        <visual>
            <origin xyz="0 0.6 0" rpy="0 0 0" />
            <xacro:box_geometry length="0.1" width="2" height="0.1" />
            <material name="m2">
                <color rgba="0.3 0.8 0.1 1.0"/>
            </material>        
        </visual>
        <collision>
            <origin xyz="0 0.6 0" rpy="0 0 0" />
            <xacro:box_geometry length="0.1" width="2" height="0.1" />
        </collision>
    </link>

    <link name="slider">
        <visual>
            <xacro:default_origin />
            <xacro:box_geometry length="0.15" width="0.15" height="0.15" />
            <material name="m3">
                <color rgba="0.8 0.2 0.1 1.0"/>
            </material>
        </visual>
        <collision>
            <xacro:default_origin />
            <xacro:box_geometry length="0.15" width="0.15" height="0.15" />
        </collision>
    </link>

    <link name="gripper">
        <visual>
            <xacro:default_origin />
            <xacro:box_geometry length="0.05" width="0.05" height="0.05" />
            <material name="m4">
                <color rgba="0.8 0.2 0.9 1.0"/>
            </material>
        </visual>
        <collision>
            <xacro:default_origin />
            <xacro:box_geometry length="0.01" width="0.01" height="0.01" />
        </collision>
    </link>

    <!-- * * * Joint Definitions * * * -->
    <joint name="base_arm" type="revolute">
        <parent link="base_link" />
        <child link="arm" />
        <limit lower="-3.1416" upper="3.1416" effort="1" velocity="3" />
        <origin xyz="0 0 0.815" rpy="0 0 0" />
        <axis xyz="0 0 1" />
    </joint>


    <joint name="arm_slider" type="prismatic">
        <parent link="arm" />
        <child link="slider" />
        <limit lower="-0.4" upper="1.2" effort="10" velocity="3" />
        <origin xyz="0 0.4 0" rpy="0 0 0" />
        <axis xyz="0 1 0" />
    </joint>

    <joint name="slider_gripper" type="prismatic">
        <parent link="slider" />
        <child link="gripper" />
        <limit lower="-0.7" upper="1.15" effort="10" velocity="3" />
        <origin xyz="0 0 0" rpy="-3.1416 0 0" />
        <axis xyz="0 0 1" />
    </joint>


</robot> 